Workbook

Sheet Start Here
A1: Seller Profit Sheet
A2: Find out which products actually make you money after every fee, shipping label, return and ad dollar.
A4: SETUP (about 10 minutes, once)
A5: 1. Settings tab: check the fee rates for the platforms you sell on (they are pre-filled with US rates as of Oct 2026, edit if yours differ). Enter your labor rate, monthly overhead and monthly ad spend.
A6: 2. Products tab: one row per product. Name must match the listing title exactly as it appears in your sales export (or fill in SKU, which is matched first).
A7: Enter material, packaging, labor minutes and what you pay for the shipping label. Yellow cells are yours to fill; grey cells calculate themselves.
A9: EACH MONTH (about 2 minutes)
A10: Etsy: Shop Manager > Settings > Options > Download Data > 'Order Items' CSV for the month. Open it, select all, copy, and paste into cell A1 of the 'Etsy Import' tab (replace what was there).
A11: Shopify: Orders > Export > 'Current page' or a date range, 'CSV for Excel'. Paste into cell A1 of the 'Shopify Import' tab.
A12: Amazon, eBay, markets, anything else: type sales into the 'Manual Sales' tab, one row per product sold.
A13: Then open 'Profit by Product'. Products marked LOSING MONEY cost you more than they bring in. 'Price Calculator' tells you what to charge to hit the margin you want.
A15: IF SOMETHING LOOKS WRONG
... A20: Google Sheets: File > Import > Upload this file > 'Replace spreadsheet'. Everything works the same.

Sheet Profit by Product
A1: Profit by Product
A2: For whatever period you pasted in. Sorted the same way as Products.
A4: Gross sales (matched products) | B4: =SUM(C11:C210)
A5: Net profit from products | B5: =SUM(H11:H210)
A6: Monthly overhead | B6: =-Settings!$B$13
A7: Store profit | B7: =B5+B6
A8: Sales not matched to a product | B8: =SUMIFS('Etsy Calc'!$J$2:$J$1501,'Etsy Calc'!$L$2:$L$1501,"⚠ not in Products")+SUMIFS('Shopify Calc'!$J$2:$J$1501,'Shopify Calc'!$L$2:$L$1501,"⚠ not in Products")+SUMIFS('Manual Sales'!$S$2:$S$1501,'Manual Sales'!$U$2:$U$1501,"⚠ not in Products") | C8: =IF(B8>0,"⚠ Some sales have no costs entered, so profit above is overstated. See Start Here.","")
A10: Product | B10: Units sold | C10: Gross sales | D10: Platform fees | E10: Product costs (materials, labor, label) | F10: Return allowance | G10: Ad spend share | H10: Net profit | I10: Profit per unit | J10: Margin | K10: Verdict
A11: =IF(Products!A5="","",Products!A5) | B11: =IF(A11="","",SUMIFS('Etsy Calc'!$D$2:$D$1501,'Etsy Calc'!$L$2:$L$1501,A11)+SUMIFS('Shopify Calc'!$D$2:$D$1501,'Shopify Calc'!$L$2:$L$1501,A11)+SUMIFS('Manual Sales'!$M$2:$M$1501,'Manual Sales'!$U$2:$U$1501,A11)) | C11: =IF(A11="","",SUMIFS('Etsy Calc'!$J$2:$J$1501,'Etsy Calc'!$L$2:$L$1501,A11)+SUMIFS('Shopify Calc'!$J$2:$J$1501,'Shopify Calc'!$L$2:$L$1501,A11)+SUMIFS('Manual Sales'!$S$2:$S$1501,'Manual Sales'!$U$2:$U$1501,A11)) | D11: =IF(A11="","",SUMIFS('Etsy Calc'!$M$2:$M$1501,'Etsy Calc'!$L$2:$L$1501,A11)+SUMIFS('Shopify Calc'!$M$2:$M$1501,'Shopify Calc'!$L$2:$L$1501,A11)+SUMIFS('Manual Sales'!$V$2:$V$1501,'Manual Sales'!$U$2:$U$1501,A11)) | E11: =IF(A11="","",SUMIFS('Etsy Calc'!$N$2:$N$1501,'Etsy Calc'!$L$2:$L$1501,A11)+SUMIFS('Shopify Calc'!$N$2:$N$1501,'Shopify Calc'!$L$2:$L$1501,A11)+SUMIFS('Manual Sales'!$W$2:$W$1501,'Manual Sales'!$U$2:$U$1501,A11)) | F11: =IF(A11="","",SUMIFS('Etsy Calc'!$O$2:$O$1501,'Etsy Calc'!$L$2:$L$1501,A11)+SUMIFS('Shopify Calc'!$O$2:$O$1501,'Shopify Calc'!$L$2:$L$1501,A11)+SUMIFS('Manual Sales'!$X$2:$X$1501,'Manual Sales'!$U$2:$U$1501,A11)) | G11: =IF(A11="","",IF($B$4=0,0,Settings!$B$14*C11/$B$4)) | H11: =IF(A11="","",C11-D11-E11-F11-G11) | I11: =IF(OR(A11="",N(B11)=0),"",H11/B11) | J11: =IF(OR(A11="",N(C11)=0),"",H11/C11) | K11: =IF(A11="","",IF(N(B11)=0,"No sales",IF(H11<0,"LOSING MONEY",IF(J11<0.15,"Thin margin","Healthy"))))
A12: =IF(Products!A6="","",Products!A6) | B12: =IF(A12="","",SUMIFS('Etsy Calc'!$D$2:$D$1501,'Etsy Calc'!$L$2:$L$1501,A12)+SUMIFS('Shopify Calc'!$D$2:$D$1501,'Shopify Calc'!$L$2:$L$1501,A12)+SUMIFS('Manual Sales'!$M$2:$M$1501,'Manual Sales'!$U$2:$U$1501,A12)) | C12: =IF(A12="","",SUMIFS('Etsy Calc'!$J$2:$J$1501,'Etsy Calc'!$L$2:$L$1501,A12)+SUMIFS('Shopify Calc'!$J$2:$J$1501,'Shopify Calc'!$L$2:$L$1501,A12)+SUMIFS('Manual Sales'!$S$2:$S$1501,'Manual Sales'!$U$2:$U$1501,A12)) | D12: =IF(A12="","",SUMIFS('Etsy Calc'!$M$2:$M$1501,'Etsy Calc'!$L$2:$L$1501,A12)+SUMIFS('Shopify Calc'!$M$2:$M$1501,'Shopify Calc'!$L$2:$L$1501,A12)+SUMIFS('Manual Sales'!$V$2:$V$1501,'Manual Sales'!$U$2:$U$1501,A12)) | E12: =IF(A12="","",SUMIFS('Etsy Calc'!$N$2:$N$1501,'Etsy Calc'!$L$2:$L$1501,A12)+SUMIFS('Shopify Calc'!$N$2:$N$1501,'Shopify Calc'!$L$2:$L$1501,A12)+SUMIFS('Manual Sales'!$W$2:$W$1501,'Manual Sales'!$U$2:$U$1501,A12)) | F12: =IF(A12="","",SUMIFS('Etsy Calc'!$O$2:$O$1501,'Etsy Calc'!$L$2:$L$1501,A12)+SUMIFS('Shopify Calc'!$O$2:$O$1501,'Shopify Calc'!$L$2:$L$1501,A12)+SUMIFS('Manual Sales'!$X$2:$X$1501,'Manual Sales'!$U$2:$U$1501,A12)) | G12: =IF(A12="","",IF($B$4=0,0,Settings!$B$14*C12/$B$4)) | H12: =IF(A12="","",C12-D12-E12-F12-G12) | I12: =IF(OR(A12="",N(B12)=0),"",H12/B12) | J12: =IF(OR(A12="",N(C12)=0),"",H12/C12) | K12: =IF(A12="","",IF(N(B12)=0,"No sales",IF(H12<0,"LOSING MONEY",IF(J12<0.15,"Thin margin","Healthy"))))
A13: =IF(Products!A7="","",Products!A7) | B13: =IF(A13="","",SUMIFS('Etsy Calc'!$D$2:$D$1501,'Etsy Calc'!$L$2:$L$1501,A13)+SUMIFS('Shopify Calc'!$D$2:$D$1501,'Shopify Calc'!$L$2:$L$1501,A13)+SUMIFS('Manual Sales'!$M$2:$M$1501,'Manual Sales'!$U$2:$U$1501,A13)) | C13: =IF(A13="","",SUMIFS('Etsy Calc'!$J$2:$J$1501,'Etsy Calc'!$L$2:$L$1501,A13)+SUMIFS('Shopify Calc'!$J$2:$J$1501,'Shopify Calc'!$L$2:$L$1501,A13)+SUMIFS('Manual Sales'!$S$2:$S$1501,'Manual Sales'!$U$2:$U$1501,A13)) | D13: =IF(A13="","",SUMIFS('Etsy Calc'!$M$2:$M$1501,'Etsy Calc'!$L$2:$L$1501,A13)+SUMIFS('Shopify Calc'!$M$2:$M$1501,'Shopify Calc'!$L$2:$L$1501,A13)+SUMIFS('Manual Sales'!$V$2:$V$1501,'Manual Sales'!$U$2:$U$1501,A13)) | E13: =IF(A13="","",SUMIFS('Etsy Calc'!$N$2:$N$1501,'Etsy Calc'!$L$2:$L$1501,A13)+SUMIFS('Shopify Calc'!$N$2:$N$1501,'Shopify Calc'!$L$2:$L$1501,A13)+SUMIFS('Manual Sales'!$W$2:$W$1501,'Manual Sales'!$U$2:$U$1501,A13)) | F13: =IF(A13="","",SUMIFS('Etsy Calc'!$O$2:$O$1501,'Etsy Calc'!$L$2:$L$1501,A13)+SUMIFS('Shopify Calc'!$O$2:$O$1501,'Shopify Calc'!$L$2:$L$1501,A13)+SUMIFS('Manual Sales'!$X$2:$X$1501,'Manual Sales'!$U$2:$U$1501,A13)) | G13: =IF(A13="","",IF($B$4=0,0,Settings!$B$14*C13/$B$4)) | H13: =IF(A13="","",C13-D13-E13-F13-G13) | I13: =IF(OR(A13="",N(B13)=0),"",H13/B13) | J13: =IF(OR(A13="",N(C13)=0),"",H13/C13) | K13: =IF(A13="","",IF(N(B13)=0,"No sales",IF(H13<0,"LOSING MONEY",IF(J13<0.15,"Thin margin","Healthy"))))
A14: =IF(Products!A8="","",Products!A8) | B14: =IF(A14="","",SUMIFS('Etsy Calc'!$D$2:$D$1501,'Etsy Calc'!$L$2:$L$1501,A14)+SUMIFS('Shopify Calc'!$D$2:$D$1501,'Shopify Calc'!$L$2:$L$1501,A14)+SUMIFS('Manual Sales'!$M$2:$M$1501,'Manual Sales'!$U$2:$U$1501,A14)) | C14: =IF(A14="","",SUMIFS('Etsy Calc'!$J$2:$J$1501,'Etsy Calc'!$L$2:$L$1501,A14)+SUMIFS('Shopify Calc'!$J$2:$J$1501,'Shopify Calc'!$L$2:$L$1501,A14)+SUMIFS('Manual Sales'!$S$2:$S$1501,'Manual Sales'!$U$2:$U$1501,A14)) | D14: =IF(A14="","",SUMIFS('Etsy Calc'!$M$2:$M$1501,'Etsy Calc'!$L$2:$L$1501,A14)+SUMIFS('Shopify Calc'!$M$2:$M$1501,'Shopify Calc'!$L$2:$L$1501,A14)+SUMIFS('Manual Sales'!$V$2:$V$1501,'Manual Sales'!$U$2:$U$1501,A14)) | E14: =IF(A14="","",SUMIFS('Etsy Calc'!$N$2:$N$1501,'Etsy Calc'!$L$2:$L$1501,A14)+SUMIFS('Shopify Calc'!$N$2:$N$1501,'Shopify Calc'!$L$2:$L$1501,A14)+SUMIFS('Manual Sales'!$W$2:$W$1501,'Manual Sales'!$U$2:$U$1501,A14)) | F14: =IF(A14="","",SUMIFS('Etsy Calc'!$O$2:$O$1501,'Etsy Calc'!$L$2:$L$1501,A14)+SUMIFS('Shopify Calc'!$O$2:$O$1501,'Shopify Calc'!$L$2:$L$1501,A14)+SUMIFS('Manual Sales'!$X$2:$X$1501,'Manual Sales'!$U$2:$U$1501,A14)) | G14: =IF(A14="","",IF($B$4=0,0,Settings!$B$14*C14/$B$4)) | H14: =IF(A14="","",C14-D14-E14-F14-G14) | I14: =IF(OR(A14="",N(B14)=0),"",H14/B14) | J14: =IF(OR(A14="",N(C14)=0),"",H14/C14) | K14: =IF(A14="","",IF(N(B14)=0,"No sales",IF(H14<0,"LOSING MONEY",IF(J14<0.15,"Thin margin","Healthy"))))
A15: =IF(Products!A9="","",Products!A9) | B15: =IF(A15="","",SUMIFS('Etsy Calc'!$D$2:$D$1501,'Etsy Calc'!$L$2:$L$1501,A15)+SUMIFS('Shopify Calc'!$D$2:$D$1501,'Shopify Calc'!$L$2:$L$1501,A15)+SUMIFS('Manual Sales'!$M$2:$M$1501,'Manual Sales'!$U$2:$U$1501,A15)) | C15: =IF(A15="","",SUMIFS('Etsy Calc'!$J$2:$J$1501,'Etsy Calc'!$L$2:$L$1501,A15)+SUMIFS('Shopify Calc'!$J$2:$J$1501,'Shopify Calc'!$L$2:$L$1501,A15)+SUMIFS('Manual Sales'!$S$2:$S$1501,'Manual Sales'!$U$2:$U$1501,A15)) | D15: =IF(A15="","",SUMIFS('Etsy Calc'!$M$2:$M$1501,'Etsy Calc'!$L$2:$L$1501,A15)+SUMIFS('Shopify Calc'!$M$2:$M$1501,'Shopify Calc'!$L$2:$L$1501,A15)+SUMIFS('Manual Sales'!$V$2:$V$1501,'Manual Sales'!$U$2:$U$1501,A15)) | E15: =IF(A15="","",SUMIFS('Etsy Calc'!$N$2:$N$1501,'Etsy Calc'!$L$2:$L$1501,A15)+SUMIFS('Shopify Calc'!$N$2:$N$1501,'Shopify Calc'!$L$2:$L$1501,A15)+SUMIFS('Manual Sales'!$W$2:$W$1501,'Manual Sales'!$U$2:$U$1501,A15)) | F15: =IF(A15="","",SUMIFS('Etsy Calc'!$O$2:$O$1501,'Etsy Calc'!$L$2:$L$1501,A15)+SUMIFS('Shopify Calc'!$O$2:$O$1501,'Shopify Calc'!$L$2:$L$1501,A15)+SUMIFS('Manual Sales'!$X$2:$X$1501,'Manual Sales'!$U$2:$U$1501,A15)) | G15: =IF(A15="","",IF($B$4=0,0,Settings!$B$14*C15/$B$4)) | H15: =IF(A15="","",C15-D15-E15-F15-G15) | I15: =IF(OR(A15="",N(B15)=0),"",H15/B15) | J15: =IF(OR(A15="",N(C15)=0),"",H15/C15) | K15: =IF(A15="","",IF(N(B15)=0,"No sales",IF(H15<0,"LOSING MONEY",IF(J15<0.15,"Thin margin","Healthy"))))
A16: =IF(Products!A10="","",Products!A10) | B16: =IF(A16="","",SUMIFS('Etsy Calc'!$D$2:$D$1501,'Etsy Calc'!$L$2:$L$1501,A16)+SUMIFS('Shopify Calc'!$D$2:$D$1501,'Shopify Calc'!$L$2:$L$1501,A16)+SUMIFS('Manual Sales'!$M$2:$M$1501,'Manual Sales'!$U$2:$U$1501,A16)) | C16: =IF(A16="","",SUMIFS('Etsy Calc'!$J$2:$J$1501,'Etsy Calc'!$L$2:$L$1501,A16)+SUMIFS('Shopify Calc'!$J$2:$J$1501,'Shopify Calc'!$L$2:$L$1501,A16)+SUMIFS('Manual Sales'!$S$2:$S$1501,'Manual Sales'!$U$2:$U$1501,A16)) | D16: =IF(A16="","",SUMIFS('Etsy Calc'!$M$2:$M$1501,'Etsy Calc'!$L$2:$L$1501,A16)+SUMIFS('Shopify Calc'!$M$2:$M$1501,'Shopify Calc'!$L$2:$L$1501,A16)+SUMIFS('Manual Sales'!$V$2:$V$1501,'Manual Sales'!$U$2:$U$1501,A16)) | E16: =IF(A16="","",SUMIFS('Etsy Calc'!$N$2:$N$1501,'Etsy Calc'!$L$2:$L$1501,A16)+SUMIFS('Shopify Calc'!$N$2:$N$1501,'Shopify Calc'!$L$2:$L$1501,A16)+SUMIFS('Manual Sales'!$W$2:$W$1501,'Manual Sales'!$U$2:$U$1501,A16)) | F16: =IF(A16="","",SUMIFS('Etsy Calc'!$O$2:$O$1501,'Etsy Calc'!$L$2:$L$1501,A16)+SUMIFS('Shopify Calc'!$O$2:$O$1501,'Shopify Calc'!$L$2:$L$1501,A16)+SUMIFS('Manual Sales'!$X$2:$X$1501,'Manual Sales'!$U$2:$U$1501,A16)) | G16: =IF(A16="","",IF($B$4=0,0,Settings!$B$14*C16/$B$4)) | H16: =IF(A16="","",C16-D16-E16-F16-G16) | I16: =IF(OR(A16="",N(B16)=0),"",H16/B16) | J16: =IF(OR(A16="",N(C16)=0),"",H16/C16) | K16: =IF(A16="","",IF(N(B16)=0,"No sales",IF(H16<0,"LOSING MONEY",IF(J16<0.15,"Thin margin","Healthy"))))
A17: =IF(Products!A11="","",Products!A11) | B17: =IF(A17="","",SUMIFS('Etsy Calc'!$D$2:$D$1501,'Etsy Calc'!$L$2:$L$1501,A17)+SUMIFS('Shopify Calc'!$D$2:$D$1501,'Shopify Calc'!$L$2:$L$1501,A17)+SUMIFS('Manual Sales'!$M$2:$M$1501,'Manual Sales'!$U$2:$U$1501,A17)) | C17: =IF(A17="","",SUMIFS('Etsy Calc'!$J$2:$J$1501,'Etsy Calc'!$L$2:$L$1501,A17)+SUMIFS('Shopify Calc'!$J$2:$J$1501,'Shopify Calc'!$L$2:$L$1501,A17)+SUMIFS('Manual Sales'!$S$2:$S$1501,'Manual Sales'!$U$2:$U$1501,A17)) | D17: =IF(A17="","",SUMIFS('Etsy Calc'!$M$2:$M$1501,'Etsy Calc'!$L$2:$L$1501,A17)+SUMIFS('Shopify Calc'!$M$2:$M$1501,'Shopify Calc'!$L$2:$L$1501,A17)+SUMIFS('Manual Sales'!$V$2:$V$1501,'Manual Sales'!$U$2:$U$1501,A17)) | E17: =IF(A17="","",SUMIFS('Etsy Calc'!$N$2:$N$1501,'Etsy Calc'!$L$2:$L$1501,A17)+SUMIFS('Shopify Calc'!$N$2:$N$1501,'Shopify Calc'!$L$2:$L$1501,A17)+SUMIFS('Manual Sales'!$W$2:$W$1501,'Manual Sales'!$U$2:$U$1501,A17)) | F17: =IF(A17="","",SUMIFS('Etsy Calc'!$O$2:$O$1501,'Etsy Calc'!$L$2:$L$1501,A17)+SUMIFS('Shopify Calc'!$O$2:$O$1501,'Shopify Calc'!$L$2:$L$1501,A17)+SUMIFS('Manual Sales'!$X$2:$X$1501,'Manual Sales'!$U$2:$U$1501,A17)) | G17: =IF(A17="","",IF($B$4=0,0,Settings!$B$14*C17/$B$4)) | H17: =IF(A17="","",C17-D17-E17-F17-G17) | I17: =IF(OR(A17="",N(B17)=0),"",H17/B17) | J17: =IF(OR(A17="",N(C17)=0),"",H17/C17) | K17: =IF(A17="","",IF(N(B17)=0,"No sales",IF(H17<0,"LOSING MONEY",IF(J17<0.15,"Thin margin","Healthy"))))
A18: =IF(Products!A12="","",Products!A12) | B18: =IF(A18="","",SUMIFS('Etsy Calc'!$D$2:$D$1501,'Etsy Calc'!$L$2:$L$1501,A18)+SUMIFS('Shopify Calc'!$D$2:$D$1501,'Shopify Calc'!$L$2:$L$1501,A18)+SUMIFS('Manual Sales'!$M$2:$M$1501,'Manual Sales'!$U$2:$U$1501,A18)) | C18: =IF(A18="","",SUMIFS('Etsy Calc'!$J$2:$J$1501,'Etsy Calc'!$L$2:$L$1501,A18)+SUMIFS('Shopify Calc'!$J$2:$J$1501,'Shopify Calc'!$L$2:$L$1501,A18)+SUMIFS('Manual Sales'!$S$2:$S$1501,'Manual Sales'!$U$2:$U$1501,A18)) | D18: =IF(A18="","",SUMIFS('Etsy Calc'!$M$2:$M$1501,'Etsy Calc'!$L$2:$L$1501,A18)+SUMIFS('Shopify Calc'!$M$2:$M$1501,'Shopify Calc'!$L$2:$L$1501,A18)+SUMIFS('Manual Sales'!$V$2:$V$1501,'Manual Sales'!$U$2:$U$1501,A18)) | E18: =IF(A18="","",SUMIFS('Etsy Calc'!$N$2:$N$1501,'Etsy Calc'!$L$2:$L$1501,A18)+SUMIFS('Shopify Calc'!$N$2:$N$1501,'Shopify Calc'!$L$2:$L$1501,A18)+SUMIFS('Manual Sales'!$W$2:$W$1501,'Manual Sales'!$U$2:$U$1501,A18)) | F18: =IF(A18="","",SUMIFS('Etsy Calc'!$O$2:$O$1501,'Etsy Calc'!$L$2:$L$1501,A18)+SUMIFS('Shopify Calc'!$O$2:$O$1501,'Shopify Calc'!$L$2:$L$1501,A18)+SUMIFS('Manual Sales'!$X$2:$X$1501,'Manual Sales'!$U$2:$U$1501,A18)) | G18: =IF(A18="","",IF($B$4=0,0,Settings!$B$14*C18/$B$4)) | H18: =IF(A18="","",C18-D18-E18-F18-G18) | I18: =IF(OR(A18="",N(B18)=0),"",H18/B18) | J18: =IF(OR(A18="",N(C18)=0),"",H18/C18) | K18: =IF(A18="","",IF(N(B18)=0,"No sales",IF(H18<0,"LOSING MONEY",IF(J18<0.15,"Thin margin","Healthy"))))
A19: =IF(Products!A13="","",Products!A13) | B19: =IF(A19="","",SUMIFS('Etsy Calc'!$D$2:$D$1501,'Etsy Calc'!$L$2:$L$1501,A19)+SUMIFS('Shopify Calc'!$D$2:$D$1501,'Shopify Calc'!$L$2:$L$1501,A19)+SUMIFS('Manual Sales'!$M$2:$M$1501,'Manual Sales'!$U$2:$U$1501,A19)) | C19: =IF(A19="","",SUMIFS('Etsy Calc'!$J$2:$J$1501,'Etsy Calc'!$L$2:$L$1501,A19)+SUMIFS('Shopify Calc'!$J$2:$J$1501,'Shopify Calc'!$L$2:$L$1501,A19)+SUMIFS('Manual Sales'!$S$2:$S$1501,'Manual Sales'!$U$2:$U$1501,A19)) | D19: =IF(A19="","",SUMIFS('Etsy Calc'!$M$2:$M$1501,'Etsy Calc'!$L$2:$L$1501,A19)+SUMIFS('Shopify Calc'!$M$2:$M$1501,'Shopify Calc'!$L$2:$L$1501,A19)+SUMIFS('Manual Sales'!$V$2:$V$1501,'Manual Sales'!$U$2:$U$1501,A19)) | E19: =IF(A19="","",SUMIFS('Etsy Calc'!$N$2:$N$1501,'Etsy Calc'!$L$2:$L$1501,A19)+SUMIFS('Shopify Calc'!$N$2:$N$1501,'Shopify Calc'!$L$2:$L$1501,A19)+SUMIFS('Manual Sales'!$W$2:$W$1501,'Manual Sales'!$U$2:$U$1501,A19)) | F19: =IF(A19="","",SUMIFS('Etsy Calc'!$O$2:$O$1501,'Etsy Calc'!$L$2:$L$1501,A19)+SUMIFS('Shopify Calc'!$O$2:$O$1501,'Shopify Calc'!$L$2:$L$1501,A19)+SUMIFS('Manual Sales'!$X$2:$X$1501,'Manual Sales'!$U$2:$U$1501,A19)) | G19: =IF(A19="","",IF($B$4=0,0,Settings!$B$14*C19/$B$4)) | H19: =IF(A19="","",C19-D19-E19-F19-G19) | I19: =IF(OR(A19="",N(B19)=0),"",H19/B19) | J19: =IF(OR(A19="",N(C19)=0),"",H19/C19) | K19: =IF(A19="","",IF(N(B19)=0,"No sales",IF(H19<0,"LOSING MONEY",IF(J19<0.15,"Thin margin","Healthy"))))
A20: =IF(Products!A14="","",Products!A14) | B20: =IF(A20="","",SUMIFS('Etsy Calc'!$D$2:$D$1501,'Etsy Calc'!$L$2:$L$1501,A20)+SUMIFS('Shopify Calc'!$D$2:$D$1501,'Shopify Calc'!$L$2:$L$1501,A20)+SUMIFS('Manual Sales'!$M$2:$M$1501,'Manual Sales'!$U$2:$U$1501,A20)) | C20: =IF(A20="","",SUMIFS('Etsy Calc'!$J$2:$J$1501,'Etsy Calc'!$L$2:$L$1501,A20)+SUMIFS('Shopify Calc'!$J$2:$J$1501,'Shopify Calc'!$L$2:$L$1501,A20)+SUMIFS('Manual Sales'!$S$2:$S$1501,'Manual Sales'!$U$2:$U$1501,A20)) | D20: =IF(A20="","",SUMIFS('Etsy Calc'!$M$2:$M$1501,'Etsy Calc'!$L$2:$L$1501,A20)+SUMIFS('Shopify Calc'!$M$2:$M$1501,'Shopify Calc'!$L$2:$L$1501,A20)+SUMIFS('Manual Sales'!$V$2:$V$1501,'Manual Sales'!$U$2:$U$1501,A20)) | E20: =IF(A20="","",SUMIFS('Etsy Calc'!$N$2:$N$1501,'Etsy Calc'!$L$2:$L$1501,A20)+SUMIFS('Shopify Calc'!$N$2:$N$1501,'Shopify Calc'!$L$2:$L$1501,A20)+SUMIFS('Manual Sales'!$W$2:$W$1501,'Manual Sales'!$U$2:$U$1501,A20)) | F20: =IF(A20="","",SUMIFS('Etsy Calc'!$O$2:$O$1501,'Etsy Calc'!$L$2:$L$1501,A20)+SUMIFS('Shopify Calc'!$O$2:$O$1501,'Shopify Calc'!$L$2:$L$1501,A20)+SUMIFS('Manual Sales'!$X$2:$X$1501,'Manual Sales'!$U$2:$U$1501,A20)) | G20: =IF(A20="","",IF($B$4=0,0,Settings!$B$14*C20/$B$4)) | H20: =IF(A20="","",C20-D20-E20-F20-G20) | I20: =IF(OR(A20="",N(B20)=0),"",H20/B20) | J20: =IF(OR(A20="",N(C20)=0),"",H20/C20) | K20: =IF(A20="","",IF(N(B20)=0,"No sales",IF(H20<0,"LOSING MONEY",IF(J20<0.15,"Thin margin","Healthy"))))
A21: =IF(Products!A15="","",Products!A15) | B21: =IF(A21="","",SUMIFS('Etsy Calc'!$D$2:$D$1501,'Etsy Calc'!$L$2:$L$1501,A21)+SUMIFS('Shopify Calc'!$D$2:$D$1501,'Shopify Calc'!$L$2:$L$1501,A21)+SUMIFS('Manual Sales'!$M$2:$M$1501,'Manual Sales'!$U$2:$U$1501,A21)) | C21: =IF(A21="","",SUMIFS('Etsy Calc'!$J$2:$J$1501,'Etsy Calc'!$L$2:$L$1501,A21)+SUMIFS('Shopify Calc'!$J$2:$J$1501,'Shopify Calc'!$L$2:$L$1501,A21)+SUMIFS('Manual Sales'!$S$2:$S$1501,'Manual Sales'!$U$2:$U$1501,A21)) | D21: =IF(A21="","",SUMIFS('Etsy Calc'!$M$2:$M$1501,'Etsy Calc'!$L$2:$L$1501,A21)+SUMIFS('Shopify Calc'!$M$2:$M$1501,'Shopify Calc'!$L$2:$L$1501,A21)+SUMIFS('Manual Sales'!$V$2:$V$1501,'Manual Sales'!$U$2:$U$1501,A21)) | E21: =IF(A21="","",SUMIFS('Etsy Calc'!$N$2:$N$1501,'Etsy Calc'!$L$2:$L$1501,A21)+SUMIFS('Shopify Calc'!$N$2:$N$1501,'Shopify Calc'!$L$2:$L$1501,A21)+SUMIFS('Manual Sales'!$W$2:$W$1501,'Manual Sales'!$U$2:$U$1501,A21)) | F21: =IF(A21="","",SUMIFS('Etsy Calc'!$O$2:$O$1501,'Etsy Calc'!$L$2:$L$1501,A21)+SUMIFS('Shopify Calc'!$O$2:$O$1501,'Shopify Calc'!$L$2:$L$1501,A21)+SUMIFS('Manual Sales'!$X$2:$X$1501,'Manual Sales'!$U$2:$U$1501,A21)) | G21: =IF(A21="","",IF($B$4=0,0,Settings!$B$14*C21/$B$4)) | H21: =IF(A21="","",C21-D21-E21-F21-G21) | I21: =IF(OR(A21="",N(B21)=0),"",H21/B21) | J21: =IF(OR(A21="",N(C21)=0),"",H21/C21) | K21: =IF(A21="","",IF(N(B21)=0,"No sales",IF(H21<0,"LOSING MONEY",IF(J21<0.15,"Thin margin","Healthy"))))
A22: =IF(Products!A16="","",Products!A16) | B22: =IF(A22="","",SUMIFS('Etsy Calc'!$D$2:$D$1501,'Etsy Calc'!$L$2:$L$1501,A22)+SUMIFS('Shopify Calc'!$D$2:$D$1501,'Shopify Calc'!$L$2:$L$1501,A22)+SUMIFS('Manual Sales'!$M$2:$M$1501,'Manual Sales'!$U$2:$U$1501,A22)) | C22: =IF(A22="","",SUMIFS('Etsy Calc'!$J$2:$J$1501,'Etsy Calc'!$L$2:$L$1501,A22)+SUMIFS('Shopify Calc'!$J$2:$J$1501,'Shopify Calc'!$L$2:$L$1501,A22)+SUMIFS('Manual Sales'!$S$2:$S$1501,'Manual Sales'!$U$2:$U$1501,A22)) | D22: =IF(A22="","",SUMIFS('Etsy Calc'!$M$2:$M$1501,'Etsy Calc'!$L$2:$L$1501,A22)+SUMIFS('Shopify Calc'!$M$2:$M$1501,'Shopify Calc'!$L$2:$L$1501,A22)+SUMIFS('Manual Sales'!$V$2:$V$1501,'Manual Sales'!$U$2:$U$1501,A22)) | E22: =IF(A22="","",SUMIFS('Etsy Calc'!$N$2:$N$1501,'Etsy Calc'!$L$2:$L$1501,A22)+SUMIFS('Shopify Calc'!$N$2:$N$1501,'Shopify Calc'!$L$2:$L$1501,A22)+SUMIFS('Manual Sales'!$W$2:$W$1501,'Manual Sales'!$U$2:$U$1501,A22)) | F22: =IF(A22="","",SUMIFS('Etsy Calc'!$O$2:$O$1501,'Etsy Calc'!$L$2:$L$1501,A22)+SUMIFS('Shopify Calc'!$O$2:$O$1501,'Shopify Calc'!$L$2:$L$1501,A22)+SUMIFS('Manual Sales'!$X$2:$X$1501,'Manual Sales'!$U$2:$U$1501,A22)) | G22: =IF(A22="","",IF($B$4=0,0,Settings!$B$14*C22/$B$4)) | H22: =IF(A22="","",C22-D22-E22-F22-G22) | I22: =IF(OR(A22="",N(B22)=0),"",H22/B22) | J22: =IF(OR(A22="",N(C22)=0),"",H22/C22) | K22: =IF(A22="","",IF(N(B22)=0,"No sales",IF(H22<0,"LOSING MONEY",IF(J22<0.15,"Thin margin","Healthy"))))
... A210: =IF(Products!A204="","",Products!A204) | B210: =IF(A210="","",SUMIFS('Etsy Calc'!$D$2:$D$1501,'Etsy Calc'!$L$2:$L$1501,A210)+SUMIFS('Shopify Calc'!$D$2:$D$1501,'Shopify Calc'!$L$2:$L$1501,A210)+SUMIFS('Manual Sales'!$M$2:$M$1501,'Manual Sales'!$U$2:$U$1501,A210)) | C210: =IF(A210="","",SUMIFS('Etsy Calc'!$J$2:$J$1501,'Etsy Calc'!$L$2:$L$1501,A210)+SUMIFS('Shopify Calc'!$J$2:$J$1501,'Shopify Calc'!$L$2:$L$1501,A210)+SUMIFS('Manual Sales'!$S$2:$S$1501,'Manual Sales'!$U$2:$U$1501,A210)) | D210: =IF(A210="","",SUMIFS('Etsy Calc'!$M$2:$M$1501,'Etsy Calc'!$L$2:$L$1501,A210)+SUMIFS('Shopify Calc'!$M$2:$M$1501,'Shopify Calc'!$L$2:$L$1501,A210)+SUMIFS('Manual Sales'!$V$2:$V$1501,'Manual Sales'!$U$2:$U$1501,A210)) | E210: =IF(A210="","",SUMIFS('Etsy Calc'!$N$2:$N$1501,'Etsy Calc'!$L$2:$L$1501,A210)+SUMIFS('Shopify Calc'!$N$2:$N$1501,'Shopify Calc'!$L$2:$L$1501,A210)+SUMIFS('Manual Sales'!$W$2:$W$1501,'Manual Sales'!$U$2:$U$1501,A210)) | F210: =IF(A210="","",SUMIFS('Etsy Calc'!$O$2:$O$1501,'Etsy Calc'!$L$2:$L$1501,A210)+SUMIFS('Shopify Calc'!$O$2:$O$1501,'Shopify Calc'!$L$2:$L$1501,A210)+SUMIFS('Manual Sales'!$X$2:$X$1501,'Manual Sales'!$U$2:$U$1501,A210)) | G210: =IF(A210="","",IF($B$4=0,0,Settings!$B$14*C210/$B$4)) | H210: =IF(A210="","",C210-D210-E210-F210-G210) | I210: =IF(OR(A210="",N(B210)=0),"",H210/B210) | J210: =IF(OR(A210="",N(C210)=0),"",H210/C210) | K210: =IF(A210="","",IF(N(B210)=0,"No sales",IF(H210<0,"LOSING MONEY",IF(J210<0.15,"Thin margin","Healthy"))))

Sheet Price Calculator
A1: Price Calculator
A2: Price = (cost + fixed fees) / (1 - fee % - return rate - target margin). Fees are a % of the sale price, not of your cost, which is why 'cost x 2' often loses money.
A4: Product | B4: Platform | C4: Total cost per unit | D4: Target margin | E4: Your current price | F4: Price to hit target | G4: Profit per unit at current price | H4: Margin at current price | I4: Check
A5: =IF(Products!A5="","",Products!A5) | B5: Etsy | C5: =IF(A5="","",Products!I5) | D5: 0.3 | E5: 18 | F5: =IF(A5="","",IF(1-(IFERROR(INDEX(Settings!$B$5:$B$9,MATCH(B5,Settings!$A$5:$A$9,0)),0)+IFERROR(INDEX(Settings!$E$5:$E$9,MATCH(B5,Settings!$A$5:$A$9,0)),0)+IFERROR(INDEX(Settings!$G$5:$G$9,MATCH(B5,Settings!$A$5:$A$9,0)),0)+N(Products!H5))-D5<=0,"margin too high",(C5+(IFERROR(INDEX(Settings!$C$5:$C$9,MATCH(B5,Settings!$A$5:$A$9,0)),0)+IFERROR(INDEX(Settings!$D$5:$D$9,MATCH(B5,Settings!$A$5:$A$9,0)),0)+IFERROR(INDEX(Settings!$F$5:$F$9,MATCH(B5,Settings!$A$5:$A$9,0)),0)))/(1-(IFERROR(INDEX(Settings!$B$5:$B$9,MATCH(B5,Settings!$A$5:$A$9,0)),0)+IFERROR(INDEX(Settings!$E$5:$E$9,MATCH(B5,Settings!$A$5:$A$9,0)),0)+IFERROR(INDEX(Settings!$G$5:$G$9,MATCH(B5,Settings!$A$5:$A$9,0)),0)+N(Products!H5))-D5))) | G5: =IF(OR(A5="",N(E5)=0),"",E5*(1-(IFERROR(INDEX(Settings!$B$5:$B$9,MATCH(B5,Settings!$A$5:$A$9,0)),0)+IFERROR(INDEX(Settings!$E$5:$E$9,MATCH(B5,Settings!$A$5:$A$9,0)),0)+IFERROR(INDEX(Settings!$G$5:$G$9,MATCH(B5,Settings!$A$5:$A$9,0)),0)+N(Products!H5)))-(IFERROR(INDEX(Settings!$C$5:$C$9,MATCH(B5,Settings!$A$5:$A$9,0)),0)+IFERROR(INDEX(Settings!$D$5:$D$9,MATCH(B5,Settings!$A$5:$A$9,0)),0)+IFERROR(INDEX(Settings!$F$5:$F$9,MATCH(B5,Settings!$A$5:$A$9,0)),0))-C5) | H5: =IF(OR(A5="",N(E5)=0),"",G5/E5) | I5: =IF(OR(A5="",N(E5)=0),"",IF(G5<0,"Loses money at this price",IF(E5<F5,"Below target: raise to "&TEXT(F5,"$0.00"),"On target")))
A6: =IF(Products!A6="","",Products!A6) | B6: Etsy | C6: =IF(A6="","",Products!I6) | D6: 0.3 | E6: 28 | F6: =IF(A6="","",IF(1-(IFERROR(INDEX(Settings!$B$5:$B$9,MATCH(B6,Settings!$A$5:$A$9,0)),0)+IFERROR(INDEX(Settings!$E$5:$E$9,MATCH(B6,Settings!$A$5:$A$9,0)),0)+IFERROR(INDEX(Settings!$G$5:$G$9,MATCH(B6,Settings!$A$5:$A$9,0)),0)+N(Products!H6))-D6<=0,"margin too high",(C6+(IFERROR(INDEX(Settings!$C$5:$C$9,MATCH(B6,Settings!$A$5:$A$9,0)),0)+IFERROR(INDEX(Settings!$D$5:$D$9,MATCH(B6,Settings!$A$5:$A$9,0)),0)+IFERROR(INDEX(Settings!$F$5:$F$9,MATCH(B6,Settings!$A$5:$A$9,0)),0)))/(1-(IFERROR(INDEX(Settings!$B$5:$B$9,MATCH(B6,Settings!$A$5:$A$9,0)),0)+IFERROR(INDEX(Settings!$E$5:$E$9,MATCH(B6,Settings!$A$5:$A$9,0)),0)+IFERROR(INDEX(Settings!$G$5:$G$9,MATCH(B6,Settings!$A$5:$A$9,0)),0)+N(Products!H6))-D6))) | G6: =IF(OR(A6="",N(E6)=0),"",E6*(1-(IFERROR(INDEX(Settings!$B$5:$B$9,MATCH(B6,Settings!$A$5:$A$9,0)),0)+IFERROR(INDEX(Settings!$E$5:$E$9,MATCH(B6,Settings!$A$5:$A$9,0)),0)+IFERROR(INDEX(Settings!$G$5:$G$9,MATCH(B6,Settings!$A$5:$A$9,0)),0)+N(Products!H6)))-(IFERROR(INDEX(Settings!$C$5:$C$9,MATCH(B6,Settings!$A$5:$A$9,0)),0)+IFERROR(INDEX(Settings!$D$5:$D$9,MATCH(B6,Settings!$A$5:$A$9,0)),0)+IFERROR(INDEX(Settings!$F$5:$F$9,MATCH(B6,Settings!$A$5:$A$9,0)),0))-C6) | H6: =IF(OR(A6="",N(E6)=0),"",G6/E6) | I6: =IF(OR(A6="",N(E6)=0),"",IF(G6<0,"Loses money at this price",IF(E6<F6,"Below target: raise to "&TEXT(F6,"$0.00"),"On target")))
A7: =IF(Products!A7="","",Products!A7) | B7: Etsy | C7: =IF(A7="","",Products!I7) | D7: 0.3 | E7: 6 | F7: =IF(A7="","",IF(1-(IFERROR(INDEX(Settings!$B$5:$B$9,MATCH(B7,Settings!$A$5:$A$9,0)),0)+IFERROR(INDEX(Settings!$E$5:$E$9,MATCH(B7,Settings!$A$5:$A$9,0)),0)+IFERROR(INDEX(Settings!$G$5:$G$9,MATCH(B7,Settings!$A$5:$A$9,0)),0)+N(Products!H7))-D7<=0,"margin too high",(C7+(IFERROR(INDEX(Settings!$C$5:$C$9,MATCH(B7,Settings!$A$5:$A$9,0)),0)+IFERROR(INDEX(Settings!$D$5:$D$9,MATCH(B7,Settings!$A$5:$A$9,0)),0)+IFERROR(INDEX(Settings!$F$5:$F$9,MATCH(B7,Settings!$A$5:$A$9,0)),0)))/(1-(IFERROR(INDEX(Settings!$B$5:$B$9,MATCH(B7,Settings!$A$5:$A$9,0)),0)+IFERROR(INDEX(Settings!$E$5:$E$9,MATCH(B7,Settings!$A$5:$A$9,0)),0)+IFERROR(INDEX(Settings!$G$5:$G$9,MATCH(B7,Settings!$A$5:$A$9,0)),0)+N(Products!H7))-D7))) | G7: =IF(OR(A7="",N(E7)=0),"",E7*(1-(IFERROR(INDEX(Settings!$B$5:$B$9,MATCH(B7,Settings!$A$5:$A$9,0)),0)+IFERROR(INDEX(Settings!$E$5:$E$9,MATCH(B7,Settings!$A$5:$A$9,0)),0)+IFERROR(INDEX(Settings!$G$5:$G$9,MATCH(B7,Settings!$A$5:$A$9,0)),0)+N(Products!H7)))-(IFERROR(INDEX(Settings!$C$5:$C$9,MATCH(B7,Settings!$A$5:$A$9,0)),0)+IFERROR(INDEX(Settings!$D$5:$D$9,MATCH(B7,Settings!$A$5:$A$9,0)),0)+IFERROR(INDEX(Settings!$F$5:$F$9,MATCH(B7,Settings!$A$5:$A$9,0)),0))-C7) | H7: =IF(OR(A7="",N(E7)=0),"",G7/E7) | I7: =IF(OR(A7="",N(E7)=0),"",IF(G7<0,"Loses money at this price",IF(E7<F7,"Below target: raise to "&TEXT(F7,"$0.00"),"On target")))
A8: =IF(Products!A8="","",Products!A8) | B8: Amazon | C8: =IF(A8="","",Products!I8) | D8: 0.3 | E8: 24 | F8: =IF(A8="","",IF(1-(IFERROR(INDEX(Settings!$B$5:$B$9,MATCH(B8,Settings!$A$5:$A$9,0)),0)+IFERROR(INDEX(Settings!$E$5:$E$9,MATCH(B8,Settings!$A$5:$A$9,0)),0)+IFERROR(INDEX(Settings!$G$5:$G$9,MATCH(B8,Settings!$A$5:$A$9,0)),0)+N(Products!H8))-D8<=0,"margin too high",(C8+(IFERROR(INDEX(Settings!$C$5:$C$9,MATCH(B8,Settings!$A$5:$A$9,0)),0)+IFERROR(INDEX(Settings!$D$5:$D$9,MATCH(B8,Settings!$A$5:$A$9,0)),0)+IFERROR(INDEX(Settings!$F$5:$F$9,MATCH(B8,Settings!$A$5:$A$9,0)),0)))/(1-(IFERROR(INDEX(Settings!$B$5:$B$9,MATCH(B8,Settings!$A$5:$A$9,0)),0)+IFERROR(INDEX(Settings!$E$5:$E$9,MATCH(B8,Settings!$A$5:$A$9,0)),0)+IFERROR(INDEX(Settings!$G$5:$G$9,MATCH(B8,Settings!$A$5:$A$9,0)),0)+N(Products!H8))-D8))) | G8: =IF(OR(A8="",N(E8)=0),"",E8*(1-(IFERROR(INDEX(Settings!$B$5:$B$9,MATCH(B8,Settings!$A$5:$A$9,0)),0)+IFERROR(INDEX(Settings!$E$5:$E$9,MATCH(B8,Settings!$A$5:$A$9,0)),0)+IFERROR(INDEX(Settings!$G$5:$G$9,MATCH(B8,Settings!$A$5:$A$9,0)),0)+N(Products!H8)))-(IFERROR(INDEX(Settings!$C$5:$C$9,MATCH(B8,Settings!$A$5:$A$9,0)),0)+IFERROR(INDEX(Settings!$D$5:$D$9,MATCH(B8,Settings!$A$5:$A$9,0)),0)+IFERROR(INDEX(Settings!$F$5:$F$9,MATCH(B8,Settings!$A$5:$A$9,0)),0))-C8) | H8: =IF(OR(A8="",N(E8)=0),"",G8/E8) | I8: =IF(OR(A8="",N(E8)=0),"",IF(G8<0,"Loses money at this price",IF(E8<F8,"Below target: raise to "&TEXT(F8,"$0.00"),"On target")))
A9: =IF(Products!A9="","",Products!A9) | B9: Etsy | C9: =IF(A9="","",Products!I9) | D9: 0.3 | F9: =IF(A9="","",IF(1-(IFERROR(INDEX(Settings!$B$5:$B$9,MATCH(B9,Settings!$A$5:$A$9,0)),0)+IFERROR(INDEX(Settings!$E$5:$E$9,MATCH(B9,Settings!$A$5:$A$9,0)),0)+IFERROR(INDEX(Settings!$G$5:$G$9,MATCH(B9,Settings!$A$5:$A$9,0)),0)+N(Products!H9))-D9<=0,"margin too high",(C9+(IFERROR(INDEX(Settings!$C$5:$C$9,MATCH(B9,Settings!$A$5:$A$9,0)),0)+IFERROR(INDEX(Settings!$D$5:$D$9,MATCH(B9,Settings!$A$5:$A$9,0)),0)+IFERROR(INDEX(Settings!$F$5:$F$9,MATCH(B9,Settings!$A$5:$A$9,0)),0)))/(1-(IFERROR(INDEX(Settings!$B$5:$B$9,MATCH(B9,Settings!$A$5:$A$9,0)),0)+IFERROR(INDEX(Settings!$E$5:$E$9,MATCH(B9,Settings!$A$5:$A$9,0)),0)+IFERROR(INDEX(Settings!$G$5:$G$9,MATCH(B9,Settings!$A$5:$A$9,0)),0)+N(Products!H9))-D9))) | G9: =IF(OR(A9="",N(E9)=0),"",E9*(1-(IFERROR(INDEX(Settings!$B$5:$B$9,MATCH(B9,Settings!$A$5:$A$9,0)),0)+IFERROR(INDEX(Settings!$E$5:$E$9,MATCH(B9,Settings!$A$5:$A$9,0)),0)+IFERROR(INDEX(Settings!$G$5:$G$9,MATCH(B9,Settings!$A$5:$A$9,0)),0)+N(Products!H9)))-(IFERROR(INDEX(Settings!$C$5:$C$9,MATCH(B9,Settings!$A$5:$A$9,0)),0)+IFERROR(INDEX(Settings!$D$5:$D$9,MATCH(B9,Settings!$A$5:$A$9,0)),0)+IFERROR(INDEX(Settings!$F$5:$F$9,MATCH(B9,Settings!$A$5:$A$9,0)),0))-C9) | H9: =IF(OR(A9="",N(E9)=0),"",G9/E9) | I9: =IF(OR(A9="",N(E9)=0),"",IF(G9<0,"Loses money at this price",IF(E9<F9,"Below target: raise to "&TEXT(F9,"$0.00"),"On target")))
A10: =IF(Products!A10="","",Products!A10) | B10: Etsy | C10: =IF(A10="","",Products!I10) | D10: 0.3 | F10: =IF(A10="","",IF(1-(IFERROR(INDEX(Settings!$B$5:$B$9,MATCH(B10,Settings!$A$5:$A$9,0)),0)+IFERROR(INDEX(Settings!$E$5:$E$9,MATCH(B10,Settings!$A$5:$A$9,0)),0)+IFERROR(INDEX(Settings!$G$5:$G$9,MATCH(B10,Settings!$A$5:$A$9,0)),0)+N(Products!H10))-D10<=0,"margin too high",(C10+(IFERROR(INDEX(Settings!$C$5:$C$9,MATCH(B10,Settings!$A$5:$A$9,0)),0)+IFERROR(INDEX(Settings!$D$5:$D$9,MATCH(B10,Settings!$A$5:$A$9,0)),0)+IFERROR(INDEX(Settings!$F$5:$F$9,MATCH(B10,Settings!$A$5:$A$9,0)),0)))/(1-(IFERROR(INDEX(Settings!$B$5:$B$9,MATCH(B10,Settings!$A$5:$A$9,0)),0)+IFERROR(INDEX(Settings!$E$5:$E$9,MATCH(B10,Settings!$A$5:$A$9,0)),0)+IFERROR(INDEX(Settings!$G$5:$G$9,MATCH(B10,Settings!$A$5:$A$9,0)),0)+N(Products!H10))-D10))) | G10: =IF(OR(A10="",N(E10)=0),"",E10*(1-(IFERROR(INDEX(Settings!$B$5:$B$9,MATCH(B10,Settings!$A$5:$A$9,0)),0)+IFERROR(INDEX(Settings!$E$5:$E$9,MATCH(B10,Settings!$A$5:$A$9,0)),0)+IFERROR(INDEX(Settings!$G$5:$G$9,MATCH(B10,Settings!$A$5:$A$9,0)),0)+N(Products!H10)))-(IFERROR(INDEX(Settings!$C$5:$C$9,MATCH(B10,Settings!$A$5:$A$9,0)),0)+IFERROR(INDEX(Settings!$D$5:$D$9,MATCH(B10,Settings!$A$5:$A$9,0)),0)+IFERROR(INDEX(Settings!$F$5:$F$9,MATCH(B10,Settings!$A$5:$A$9,0)),0))-C10) | H10: =IF(OR(A10="",N(E10)=0),"",G10/E10) | I10: =IF(OR(A10="",N(E10)=0),"",IF(G10<0,"Loses money at this price",IF(E10<F10,"Below target: raise to "&TEXT(F10,"$0.00"),"On target")))
A11: =IF(Products!A11="","",Products!A11) | B11: Etsy | C11: =IF(A11="","",Products!I11) | D11: 0.3 | F11: =IF(A11="","",IF(1-(IFERROR(INDEX(Settings!$B$5:$B$9,MATCH(B11,Settings!$A$5:$A$9,0)),0)+IFERROR(INDEX(Settings!$E$5:$E$9,MATCH(B11,Settings!$A$5:$A$9,0)),0)+IFERROR(INDEX(Settings!$G$5:$G$9,MATCH(B11,Settings!$A$5:$A$9,0)),0)+N(Products!H11))-D11<=0,"margin too high",(C11+(IFERROR(INDEX(Settings!$C$5:$C$9,MATCH(B11,Settings!$A$5:$A$9,0)),0)+IFERROR(INDEX(Settings!$D$5:$D$9,MATCH(B11,Settings!$A$5:$A$9,0)),0)+IFERROR(INDEX(Settings!$F$5:$F$9,MATCH(B11,Settings!$A$5:$A$9,0)),0)))/(1-(IFERROR(INDEX(Settings!$B$5:$B$9,MATCH(B11,Settings!$A$5:$A$9,0)),0)+IFERROR(INDEX(Settings!$E$5:$E$9,MATCH(B11,Settings!$A$5:$A$9,0)),0)+IFERROR(INDEX(Settings!$G$5:$G$9,MATCH(B11,Settings!$A$5:$A$9,0)),0)+N(Products!H11))-D11))) | G11: =IF(OR(A11="",N(E11)=0),"",E11*(1-(IFERROR(INDEX(Settings!$B$5:$B$9,MATCH(B11,Settings!$A$5:$A$9,0)),0)+IFERROR(INDEX(Settings!$E$5:$E$9,MATCH(B11,Settings!$A$5:$A$9,0)),0)+IFERROR(INDEX(Settings!$G$5:$G$9,MATCH(B11,Settings!$A$5:$A$9,0)),0)+N(Products!H11)))-(IFERROR(INDEX(Settings!$C$5:$C$9,MATCH(B11,Settings!$A$5:$A$9,0)),0)+IFERROR(INDEX(Settings!$D$5:$D$9,MATCH(B11,Settings!$A$5:$A$9,0)),0)+IFERROR(INDEX(Settings!$F$5:$F$9,MATCH(B11,Settings!$A$5:$A$9,0)),0))-C11) | H11: =IF(OR(A11="",N(E11)=0),"",G11/E11) | I11: =IF(OR(A11="",N(E11)=0),"",IF(G11<0,"Loses money at this price",IF(E11<F11,"Below target: raise to "&TEXT(F11,"$0.00"),"On target")))
A12: =IF(Products!A12="","",Products!A12) | B12: Etsy | C12: =IF(A12="","",Products!I12) | D12: 0.3 | F12: =IF(A12="","",IF(1-(IFERROR(INDEX(Settings!$B$5:$B$9,MATCH(B12,Settings!$A$5:$A$9,0)),0)+IFERROR(INDEX(Settings!$E$5:$E$9,MATCH(B12,Settings!$A$5:$A$9,0)),0)+IFERROR(INDEX(Settings!$G$5:$G$9,MATCH(B12,Settings!$A$5:$A$9,0)),0)+N(Products!H12))-D12<=0,"margin too high",(C12+(IFERROR(INDEX(Settings!$C$5:$C$9,MATCH(B12,Settings!$A$5:$A$9,0)),0)+IFERROR(INDEX(Settings!$D$5:$D$9,MATCH(B12,Settings!$A$5:$A$9,0)),0)+IFERROR(INDEX(Settings!$F$5:$F$9,MATCH(B12,Settings!$A$5:$A$9,0)),0)))/(1-(IFERROR(INDEX(Settings!$B$5:$B$9,MATCH(B12,Settings!$A$5:$A$9,0)),0)+IFERROR(INDEX(Settings!$E$5:$E$9,MATCH(B12,Settings!$A$5:$A$9,0)),0)+IFERROR(INDEX(Settings!$G$5:$G$9,MATCH(B12,Settings!$A$5:$A$9,0)),0)+N(Products!H12))-D12))) | G12: =IF(OR(A12="",N(E12)=0),"",E12*(1-(IFERROR(INDEX(Settings!$B$5:$B$9,MATCH(B12,Settings!$A$5:$A$9,0)),0)+IFERROR(INDEX(Settings!$E$5:$E$9,MATCH(B12,Settings!$A$5:$A$9,0)),0)+IFERROR(INDEX(Settings!$G$5:$G$9,MATCH(B12,Settings!$A$5:$A$9,0)),0)+N(Products!H12)))-(IFERROR(INDEX(Settings!$C$5:$C$9,MATCH(B12,Settings!$A$5:$A$9,0)),0)+IFERROR(INDEX(Settings!$D$5:$D$9,MATCH(B12,Settings!$A$5:$A$9,0)),0)+IFERROR(INDEX(Settings!$F$5:$F$9,MATCH(B12,Settings!$A$5:$A$9,0)),0))-C12) | H12: =IF(OR(A12="",N(E12)=0),"",G12/E12) | I12: =IF(OR(A12="",N(E12)=0),"",IF(G12<0,"Loses money at this price",IF(E12<F12,"Below target: raise to "&TEXT(F12,"$0.00"),"On target")))
A13: =IF(Products!A13="","",Products!A13) | B13: Etsy | C13: =IF(A13="","",Products!I13) | D13: 0.3 | F13: =IF(A13="","",IF(1-(IFERROR(INDEX(Settings!$B$5:$B$9,MATCH(B13,Settings!$A$5:$A$9,0)),0)+IFERROR(INDEX(Settings!$E$5:$E$9,MATCH(B13,Settings!$A$5:$A$9,0)),0)+IFERROR(INDEX(Settings!$G$5:$G$9,MATCH(B13,Settings!$A$5:$A$9,0)),0)+N(Products!H13))-D13<=0,"margin too high",(C13+(IFERROR(INDEX(Settings!$C$5:$C$9,MATCH(B13,Settings!$A$5:$A$9,0)),0)+IFERROR(INDEX(Settings!$D$5:$D$9,MATCH(B13,Settings!$A$5:$A$9,0)),0)+IFERROR(INDEX(Settings!$F$5:$F$9,MATCH(B13,Settings!$A$5:$A$9,0)),0)))/(1-(IFERROR(INDEX(Settings!$B$5:$B$9,MATCH(B13,Settings!$A$5:$A$9,0)),0)+IFERROR(INDEX(Settings!$E$5:$E$9,MATCH(B13,Settings!$A$5:$A$9,0)),0)+IFERROR(INDEX(Settings!$G$5:$G$9,MATCH(B13,Settings!$A$5:$A$9,0)),0)+N(Products!H13))-D13))) | G13: =IF(OR(A13="",N(E13)=0),"",E13*(1-(IFERROR(INDEX(Settings!$B$5:$B$9,MATCH(B13,Settings!$A$5:$A$9,0)),0)+IFERROR(INDEX(Settings!$E$5:$E$9,MATCH(B13,Settings!$A$5:$A$9,0)),0)+IFERROR(INDEX(Settings!$G$5:$G$9,MATCH(B13,Settings!$A$5:$A$9,0)),0)+N(Products!H13)))-(IFERROR(INDEX(Settings!$C$5:$C$9,MATCH(B13,Settings!$A$5:$A$9,0)),0)+IFERROR(INDEX(Settings!$D$5:$D$9,MATCH(B13,Settings!$A$5:$A$9,0)),0)+IFERROR(INDEX(Settings!$F$5:$F$9,MATCH(B13,Settings!$A$5:$A$9,0)),0))-C13) | H13: =IF(OR(A13="",N(E13)=0),"",G13/E13) | I13: =IF(OR(A13="",N(E13)=0),"",IF(G13<0,"Loses money at this price",IF(E13<F13,"Below target: raise to "&TEXT(F13,"$0.00"),"On target")))
A14: =IF(Products!A14="","",Products!A14) | B14: Etsy | C14: =IF(A14="","",Products!I14) | D14: 0.3 | F14: =IF(A14="","",IF(1-(IFERROR(INDEX(Settings!$B$5:$B$9,MATCH(B14,Settings!$A$5:$A$9,0)),0)+IFERROR(INDEX(Settings!$E$5:$E$9,MATCH(B14,Settings!$A$5:$A$9,0)),0)+IFERROR(INDEX(Settings!$G$5:$G$9,MATCH(B14,Settings!$A$5:$A$9,0)),0)+N(Products!H14))-D14<=0,"margin too high",(C14+(IFERROR(INDEX(Settings!$C$5:$C$9,MATCH(B14,Settings!$A$5:$A$9,0)),0)+IFERROR(INDEX(Settings!$D$5:$D$9,MATCH(B14,Settings!$A$5:$A$9,0)),0)+IFERROR(INDEX(Settings!$F$5:$F$9,MATCH(B14,Settings!$A$5:$A$9,0)),0)))/(1-(IFERROR(INDEX(Settings!$B$5:$B$9,MATCH(B14,Settings!$A$5:$A$9,0)),0)+IFERROR(INDEX(Settings!$E$5:$E$9,MATCH(B14,Settings!$A$5:$A$9,0)),0)+IFERROR(INDEX(Settings!$G$5:$G$9,MATCH(B14,Settings!$A$5:$A$9,0)),0)+N(Products!H14))-D14))) | G14: =IF(OR(A14="",N(E14)=0),"",E14*(1-(IFERROR(INDEX(Settings!$B$5:$B$9,MATCH(B14,Settings!$A$5:$A$9,0)),0)+IFERROR(INDEX(Settings!$E$5:$E$9,MATCH(B14,Settings!$A$5:$A$9,0)),0)+IFERROR(INDEX(Settings!$G$5:$G$9,MATCH(B14,Settings!$A$5:$A$9,0)),0)+N(Products!H14)))-(IFERROR(INDEX(Settings!$C$5:$C$9,MATCH(B14,Settings!$A$5:$A$9,0)),0)+IFERROR(INDEX(Settings!$D$5:$D$9,MATCH(B14,Settings!$A$5:$A$9,0)),0)+IFERROR(INDEX(Settings!$F$5:$F$9,MATCH(B14,Settings!$A$5:$A$9,0)),0))-C14) | H14: =IF(OR(A14="",N(E14)=0),"",G14/E14) | I14: =IF(OR(A14="",N(E14)=0),"",IF(G14<0,"Loses money at this price",IF(E14<F14,"Below target: raise to "&TEXT(F14,"$0.00"),"On target")))
A15: =IF(Products!A15="","",Products!A15) | B15: Etsy | C15: =IF(A15="","",Products!I15) | D15: 0.3 | F15: =IF(A15="","",IF(1-(IFERROR(INDEX(Settings!$B$5:$B$9,MATCH(B15,Settings!$A$5:$A$9,0)),0)+IFERROR(INDEX(Settings!$E$5:$E$9,MATCH(B15,Settings!$A$5:$A$9,0)),0)+IFERROR(INDEX(Settings!$G$5:$G$9,MATCH(B15,Settings!$A$5:$A$9,0)),0)+N(Products!H15))-D15<=0,"margin too high",(C15+(IFERROR(INDEX(Settings!$C$5:$C$9,MATCH(B15,Settings!$A$5:$A$9,0)),0)+IFERROR(INDEX(Settings!$D$5:$D$9,MATCH(B15,Settings!$A$5:$A$9,0)),0)+IFERROR(INDEX(Settings!$F$5:$F$9,MATCH(B15,Settings!$A$5:$A$9,0)),0)))/(1-(IFERROR(INDEX(Settings!$B$5:$B$9,MATCH(B15,Settings!$A$5:$A$9,0)),0)+IFERROR(INDEX(Settings!$E$5:$E$9,MATCH(B15,Settings!$A$5:$A$9,0)),0)+IFERROR(INDEX(Settings!$G$5:$G$9,MATCH(B15,Settings!$A$5:$A$9,0)),0)+N(Products!H15))-D15))) | G15: =IF(OR(A15="",N(E15)=0),"",E15*(1-(IFERROR(INDEX(Settings!$B$5:$B$9,MATCH(B15,Settings!$A$5:$A$9,0)),0)+IFERROR(INDEX(Settings!$E$5:$E$9,MATCH(B15,Settings!$A$5:$A$9,0)),0)+IFERROR(INDEX(Settings!$G$5:$G$9,MATCH(B15,Settings!$A$5:$A$9,0)),0)+N(Products!H15)))-(IFERROR(INDEX(Settings!$C$5:$C$9,MATCH(B15,Settings!$A$5:$A$9,0)),0)+IFERROR(INDEX(Settings!$D$5:$D$9,MATCH(B15,Settings!$A$5:$A$9,0)),0)+IFERROR(INDEX(Settings!$F$5:$F$9,MATCH(B15,Settings!$A$5:$A$9,0)),0))-C15) | H15: =IF(OR(A15="",N(E15)=0),"",G15/E15) | I15: =IF(OR(A15="",N(E15)=0),"",IF(G15<0,"Loses money at this price",IF(E15<F15,"Below target: raise to "&TEXT(F15,"$0.00"),"On target")))
A16: =IF(Products!A16="","",Products!A16) | B16: Etsy | C16: =IF(A16="","",Products!I16) | D16: 0.3 | F16: =IF(A16="","",IF(1-(IFERROR(INDEX(Settings!$B$5:$B$9,MATCH(B16,Settings!$A$5:$A$9,0)),0)+IFERROR(INDEX(Settings!$E$5:$E$9,MATCH(B16,Settings!$A$5:$A$9,0)),0)+IFERROR(INDEX(Settings!$G$5:$G$9,MATCH(B16,Settings!$A$5:$A$9,0)),0)+N(Products!H16))-D16<=0,"margin too high",(C16+(IFERROR(INDEX(Settings!$C$5:$C$9,MATCH(B16,Settings!$A$5:$A$9,0)),0)+IFERROR(INDEX(Settings!$D$5:$D$9,MATCH(B16,Settings!$A$5:$A$9,0)),0)+IFERROR(INDEX(Settings!$F$5:$F$9,MATCH(B16,Settings!$A$5:$A$9,0)),0)))/(1-(IFERROR(INDEX(Settings!$B$5:$B$9,MATCH(B16,Settings!$A$5:$A$9,0)),0)+IFERROR(INDEX(Settings!$E$5:$E$9,MATCH(B16,Settings!$A$5:$A$9,0)),0)+IFERROR(INDEX(Settings!$G$5:$G$9,MATCH(B16,Settings!$A$5:$A$9,0)),0)+N(Products!H16))-D16))) | G16: =IF(OR(A16="",N(E16)=0),"",E16*(1-(IFERROR(INDEX(Settings!$B$5:$B$9,MATCH(B16,Settings!$A$5:$A$9,0)),0)+IFERROR(INDEX(Settings!$E$5:$E$9,MATCH(B16,Settings!$A$5:$A$9,0)),0)+IFERROR(INDEX(Settings!$G$5:$G$9,MATCH(B16,Settings!$A$5:$A$9,0)),0)+N(Products!H16)))-(IFERROR(INDEX(Settings!$C$5:$C$9,MATCH(B16,Settings!$A$5:$A$9,0)),0)+IFERROR(INDEX(Settings!$D$5:$D$9,MATCH(B16,Settings!$A$5:$A$9,0)),0)+IFERROR(INDEX(Settings!$F$5:$F$9,MATCH(B16,Settings!$A$5:$A$9,0)),0))-C16) | H16: =IF(OR(A16="",N(E16)=0),"",G16/E16) | I16: =IF(OR(A16="",N(E16)=0),"",IF(G16<0,"Loses money at this price",IF(E16<F16,"Below target: raise to "&TEXT(F16,"$0.00"),"On target")))
A17: =IF(Products!A17="","",Products!A17) | B17: Etsy | C17: =IF(A17="","",Products!I17) | D17: 0.3 | F17: =IF(A17="","",IF(1-(IFERROR(INDEX(Settings!$B$5:$B$9,MATCH(B17,Settings!$A$5:$A$9,0)),0)+IFERROR(INDEX(Settings!$E$5:$E$9,MATCH(B17,Settings!$A$5:$A$9,0)),0)+IFERROR(INDEX(Settings!$G$5:$G$9,MATCH(B17,Settings!$A$5:$A$9,0)),0)+N(Products!H17))-D17<=0,"margin too high",(C17+(IFERROR(INDEX(Settings!$C$5:$C$9,MATCH(B17,Settings!$A$5:$A$9,0)),0)+IFERROR(INDEX(Settings!$D$5:$D$9,MATCH(B17,Settings!$A$5:$A$9,0)),0)+IFERROR(INDEX(Settings!$F$5:$F$9,MATCH(B17,Settings!$A$5:$A$9,0)),0)))/(1-(IFERROR(INDEX(Settings!$B$5:$B$9,MATCH(B17,Settings!$A$5:$A$9,0)),0)+IFERROR(INDEX(Settings!$E$5:$E$9,MATCH(B17,Settings!$A$5:$A$9,0)),0)+IFERROR(INDEX(Settings!$G$5:$G$9,MATCH(B17,Settings!$A$5:$A$9,0)),0)+N(Products!H17))-D17))) | G17: =IF(OR(A17="",N(E17)=0),"",E17*(1-(IFERROR(INDEX(Settings!$B$5:$B$9,MATCH(B17,Settings!$A$5:$A$9,0)),0)+IFERROR(INDEX(Settings!$E$5:$E$9,MATCH(B17,Settings!$A$5:$A$9,0)),0)+IFERROR(INDEX(Settings!$G$5:$G$9,MATCH(B17,Settings!$A$5:$A$9,0)),0)+N(Products!H17)))-(IFERROR(INDEX(Settings!$C$5:$C$9,MATCH(B17,Settings!$A$5:$A$9,0)),0)+IFERROR(INDEX(Settings!$D$5:$D$9,MATCH(B17,Settings!$A$5:$A$9,0)),0)+IFERROR(INDEX(Settings!$F$5:$F$9,MATCH(B17,Settings!$A$5:$A$9,0)),0))-C17) | H17: =IF(OR(A17="",N(E17)=0),"",G17/E17) | I17: =IF(OR(A17="",N(E17)=0),"",IF(G17<0,"Loses money at this price",IF(E17<F17,"Below target: raise to "&TEXT(F17,"$0.00"),"On target")))
A18: =IF(Products!A18="","",Products!A18) | B18: Etsy | C18: =IF(A18="","",Products!I18) | D18: 0.3 | F18: =IF(A18="","",IF(1-(IFERROR(INDEX(Settings!$B$5:$B$9,MATCH(B18,Settings!$A$5:$A$9,0)),0)+IFERROR(INDEX(Settings!$E$5:$E$9,MATCH(B18,Settings!$A$5:$A$9,0)),0)+IFERROR(INDEX(Settings!$G$5:$G$9,MATCH(B18,Settings!$A$5:$A$9,0)),0)+N(Products!H18))-D18<=0,"margin too high",(C18+(IFERROR(INDEX(Settings!$C$5:$C$9,MATCH(B18,Settings!$A$5:$A$9,0)),0)+IFERROR(INDEX(Settings!$D$5:$D$9,MATCH(B18,Settings!$A$5:$A$9,0)),0)+IFERROR(INDEX(Settings!$F$5:$F$9,MATCH(B18,Settings!$A$5:$A$9,0)),0)))/(1-(IFERROR(INDEX(Settings!$B$5:$B$9,MATCH(B18,Settings!$A$5:$A$9,0)),0)+IFERROR(INDEX(Settings!$E$5:$E$9,MATCH(B18,Settings!$A$5:$A$9,0)),0)+IFERROR(INDEX(Settings!$G$5:$G$9,MATCH(B18,Settings!$A$5:$A$9,0)),0)+N(Products!H18))-D18))) | G18: =IF(OR(A18="",N(E18)=0),"",E18*(1-(IFERROR(INDEX(Settings!$B$5:$B$9,MATCH(B18,Settings!$A$5:$A$9,0)),0)+IFERROR(INDEX(Settings!$E$5:$E$9,MATCH(B18,Settings!$A$5:$A$9,0)),0)+IFERROR(INDEX(Settings!$G$5:$G$9,MATCH(B18,Settings!$A$5:$A$9,0)),0)+N(Products!H18)))-(IFERROR(INDEX(Settings!$C$5:$C$9,MATCH(B18,Settings!$A$5:$A$9,0)),0)+IFERROR(INDEX(Settings!$D$5:$D$9,MATCH(B18,Settings!$A$5:$A$9,0)),0)+IFERROR(INDEX(Settings!$F$5:$F$9,MATCH(B18,Settings!$A$5:$A$9,0)),0))-C18) | H18: =IF(OR(A18="",N(E18)=0),"",G18/E18) | I18: =IF(OR(A18="",N(E18)=0),"",IF(G18<0,"Loses money at this price",IF(E18<F18,"Below target: raise to "&TEXT(F18,"$0.00"),"On target")))
A19: =IF(Products!A19="","",Products!A19) | B19: Etsy | C19: =IF(A19="","",Products!I19) | D19: 0.3 | F19: =IF(A19="","",IF(1-(IFERROR(INDEX(Settings!$B$5:$B$9,MATCH(B19,Settings!$A$5:$A$9,0)),0)+IFERROR(INDEX(Settings!$E$5:$E$9,MATCH(B19,Settings!$A$5:$A$9,0)),0)+IFERROR(INDEX(Settings!$G$5:$G$9,MATCH(B19,Settings!$A$5:$A$9,0)),0)+N(Products!H19))-D19<=0,"margin too high",(C19+(IFERROR(INDEX(Settings!$C$5:$C$9,MATCH(B19,Settings!$A$5:$A$9,0)),0)+IFERROR(INDEX(Settings!$D$5:$D$9,MATCH(B19,Settings!$A$5:$A$9,0)),0)+IFERROR(INDEX(Settings!$F$5:$F$9,MATCH(B19,Settings!$A$5:$A$9,0)),0)))/(1-(IFERROR(INDEX(Settings!$B$5:$B$9,MATCH(B19,Settings!$A$5:$A$9,0)),0)+IFERROR(INDEX(Settings!$E$5:$E$9,MATCH(B19,Settings!$A$5:$A$9,0)),0)+IFERROR(INDEX(Settings!$G$5:$G$9,MATCH(B19,Settings!$A$5:$A$9,0)),0)+N(Products!H19))-D19))) | G19: =IF(OR(A19="",N(E19)=0),"",E19*(1-(IFERROR(INDEX(Settings!$B$5:$B$9,MATCH(B19,Settings!$A$5:$A$9,0)),0)+IFERROR(INDEX(Settings!$E$5:$E$9,MATCH(B19,Settings!$A$5:$A$9,0)),0)+IFERROR(INDEX(Settings!$G$5:$G$9,MATCH(B19,Settings!$A$5:$A$9,0)),0)+N(Products!H19)))-(IFERROR(INDEX(Settings!$C$5:$C$9,MATCH(B19,Settings!$A$5:$A$9,0)),0)+IFERROR(INDEX(Settings!$D$5:$D$9,MATCH(B19,Settings!$A$5:$A$9,0)),0)+IFERROR(INDEX(Settings!$F$5:$F$9,MATCH(B19,Settings!$A$5:$A$9,0)),0))-C19) | H19: =IF(OR(A19="",N(E19)=0),"",G19/E19) | I19: =IF(OR(A19="",N(E19)=0),"",IF(G19<0,"Loses money at this price",IF(E19<F19,"Below target: raise to "&TEXT(F19,"$0.00"),"On target")))
A20: =IF(Products!A20="","",Products!A20) | B20: Etsy | C20: =IF(A20="","",Products!I20) | D20: 0.3 | F20: =IF(A20="","",IF(1-(IFERROR(INDEX(Settings!$B$5:$B$9,MATCH(B20,Settings!$A$5:$A$9,0)),0)+IFERROR(INDEX(Settings!$E$5:$E$9,MATCH(B20,Settings!$A$5:$A$9,0)),0)+IFERROR(INDEX(Settings!$G$5:$G$9,MATCH(B20,Settings!$A$5:$A$9,0)),0)+N(Products!H20))-D20<=0,"margin too high",(C20+(IFERROR(INDEX(Settings!$C$5:$C$9,MATCH(B20,Settings!$A$5:$A$9,0)),0)+IFERROR(INDEX(Settings!$D$5:$D$9,MATCH(B20,Settings!$A$5:$A$9,0)),0)+IFERROR(INDEX(Settings!$F$5:$F$9,MATCH(B20,Settings!$A$5:$A$9,0)),0)))/(1-(IFERROR(INDEX(Settings!$B$5:$B$9,MATCH(B20,Settings!$A$5:$A$9,0)),0)+IFERROR(INDEX(Settings!$E$5:$E$9,MATCH(B20,Settings!$A$5:$A$9,0)),0)+IFERROR(INDEX(Settings!$G$5:$G$9,MATCH(B20,Settings!$A$5:$A$9,0)),0)+N(Products!H20))-D20))) | G20: =IF(OR(A20="",N(E20)=0),"",E20*(1-(IFERROR(INDEX(Settings!$B$5:$B$9,MATCH(B20,Settings!$A$5:$A$9,0)),0)+IFERROR(INDEX(Settings!$E$5:$E$9,MATCH(B20,Settings!$A$5:$A$9,0)),0)+IFERROR(INDEX(Settings!$G$5:$G$9,MATCH(B20,Settings!$A$5:$A$9,0)),0)+N(Products!H20)))-(IFERROR(INDEX(Settings!$C$5:$C$9,MATCH(B20,Settings!$A$5:$A$9,0)),0)+IFERROR(INDEX(Settings!$D$5:$D$9,MATCH(B20,Settings!$A$5:$A$9,0)),0)+IFERROR(INDEX(Settings!$F$5:$F$9,MATCH(B20,Settings!$A$5:$A$9,0)),0))-C20) | H20: =IF(OR(A20="",N(E20)=0),"",G20/E20) | I20: =IF(OR(A20="",N(E20)=0),"",IF(G20<0,"Loses money at this price",IF(E20<F20,"Below target: raise to "&TEXT(F20,"$0.00"),"On target")))
... A204: =IF(Products!A204="","",Products!A204) | B204: Etsy | C204: =IF(A204="","",Products!I204) | D204: 0.3 | F204: =IF(A204="","",IF(1-(IFERROR(INDEX(Settings!$B$5:$B$9,MATCH(B204,Settings!$A$5:$A$9,0)),0)+IFERROR(INDEX(Settings!$E$5:$E$9,MATCH(B204,Settings!$A$5:$A$9,0)),0)+IFERROR(INDEX(Settings!$G$5:$G$9,MATCH(B204,Settings!$A$5:$A$9,0)),0)+N(Products!H204))-D204<=0,"margin too high",(C204+(IFERROR(INDEX(Settings!$C$5:$C$9,MATCH(B204,Settings!$A$5:$A$9,0)),0)+IFERROR(INDEX(Settings!$D$5:$D$9,MATCH(B204,Settings!$A$5:$A$9,0)),0)+IFERROR(INDEX(Settings!$F$5:$F$9,MATCH(B204,Settings!$A$5:$A$9,0)),0)))/(1-(IFERROR(INDEX(Settings!$B$5:$B$9,MATCH(B204,Settings!$A$5:$A$9,0)),0)+IFERROR(INDEX(Settings!$E$5:$E$9,MATCH(B204,Settings!$A$5:$A$9,0)),0)+IFERROR(INDEX(Settings!$G$5:$G$9,MATCH(B204,Settings!$A$5:$A$9,0)),0)+N(Products!H204))-D204))) | G204: =IF(OR(A204="",N(E204)=0),"",E204*(1-(IFERROR(INDEX(Settings!$B$5:$B$9,MATCH(B204,Settings!$A$5:$A$9,0)),0)+IFERROR(INDEX(Settings!$E$5:$E$9,MATCH(B204,Settings!$A$5:$A$9,0)),0)+IFERROR(INDEX(Settings!$G$5:$G$9,MATCH(B204,Settings!$A$5:$A$9,0)),0)+N(Products!H204)))-(IFERROR(INDEX(Settings!$C$5:$C$9,MATCH(B204,Settings!$A$5:$A$9,0)),0)+IFERROR(INDEX(Settings!$D$5:$D$9,MATCH(B204,Settings!$A$5:$A$9,0)),0)+IFERROR(INDEX(Settings!$F$5:$F$9,MATCH(B204,Settings!$A$5:$A$9,0)),0))-C204) | H204: =IF(OR(A204="",N(E204)=0),"",G204/E204) | I204: =IF(OR(A204="",N(E204)=0),"",IF(G204<0,"Loses money at this price",IF(E204<F204,"Below target: raise to "&TEXT(F204,"$0.00"),"On target")))

Sheet Settings
A1: Settings
A3: Platform fees
A4: Platform | B4: Sale fee % (of item + shipping) | C4: Fixed fee per order | D4: Fixed fee per unit | E4: Payment % | F4: Payment fixed per order | G4: Ads fee % (e.g. offsite ads) | H4: Notes
A5: Etsy | B5: 0.065 | C5: 0 | D5: 0.2 | E5: 0.03 | F5: 0.25 | G5: 0 | H5: 6.5% transaction, $0.20 listing renewal per unit sold, 3% + $0.25 payment (US). Offsite ads: 15% or 12% if you get them.
A6: Shopify | B6: 0 | C6: 0 | D6: 0 | E6: 0.029 | F6: 0.3 | G6: 0 | H6: Basic plan, Shopify Payments online rate. Plan fee goes in overhead.
A7: Amazon | B7: 0.15 | C7: 0 | D7: 0 | E7: 0 | F7: 0 | G7: 0 | H7: 15% referral (most categories). Put FBA fees per unit in Products > 'Other per-unit fees'.
A8: eBay | B8: 0.136 | C8: 0.4 | D8: 0 | E8: 0 | F8: 0 | G8: 0 | H8: 13.6% final value fee + $0.40 per order (most categories).
A9: Other | B9: 0 | C9: 0 | D9: 0 | E9: 0.029 | F9: 0.3 | G9: 0 | H9: Markets, your own site, etc. Edit to match your card reader.
A11: Your numbers
A12: Labor rate ($ per hour) | B12: 15
A13: Monthly overhead ($) | B13: 25 | C13: Software, plan fees, supplies not tied to one product.
A14: Monthly ad spend, all platforms ($) | B14: 40 | C14: Etsy Ads, Shopify/Meta ads, Amazon PPC. Shared across products by revenue.
A17: Import column names
A18: Each field is read from the column with this header. Fix a header here if a platform renames it.
A19: Field | B19: Etsy header | C19: Etsy col # | D19: Shopify header | E19: Shopify col #
A20: Product name | B20: Item Name | C20: =IFERROR(MATCH(B20,'Etsy Import'!$1:$1,0),"not found") | D20: Lineitem name | E20: =IFERROR(MATCH(D20,'Shopify Import'!$1:$1,0),"not found")
A21: SKU | B21: SKU | C21: =IFERROR(MATCH(B21,'Etsy Import'!$1:$1,0),"not found") | D21: Lineitem sku | E21: =IFERROR(MATCH(D21,'Shopify Import'!$1:$1,0),"not found")
A22: Order ID | B22: Order ID | C22: =IFERROR(MATCH(B22,'Etsy Import'!$1:$1,0),"not found") | D22: Name | E22: =IFERROR(MATCH(D22,'Shopify Import'!$1:$1,0),"not found")
A23: Quantity | B23: Quantity | C23: =IFERROR(MATCH(B23,'Etsy Import'!$1:$1,0),"not found") | D23: Lineitem quantity | E23: =IFERROR(MATCH(D23,'Shopify Import'!$1:$1,0),"not found")
A24: Unit price | B24: Price | C24: =IFERROR(MATCH(B24,'Etsy Import'!$1:$1,0),"not found") | D24: Lineitem price | E24: =IFERROR(MATCH(D24,'Shopify Import'!$1:$1,0),"not found")
A25: Shipping charged | B25: Order Shipping | C25: =IFERROR(MATCH(B25,'Etsy Import'!$1:$1,0),"not found") | D25: Shipping | E25: =IFERROR(MATCH(D25,'Shopify Import'!$1:$1,0),"not found")
A26: Discount | B26: Discount Amount | C26: =IFERROR(MATCH(B26,'Etsy Import'!$1:$1,0),"not found") | D26: Discount Amount | E26: =IFERROR(MATCH(D26,'Shopify Import'!$1:$1,0),"not found")
A27: Order-level amounts repeat on every item row? | B27: Yes | D27: No
A28: Yes = shipping and discount are split evenly across the items in an order. No = they are counted once, from the row where they appear.

Sheet Products
A1: Products
A2: One row per product. Yellow = you fill in. Name must match your listing title exactly (or use SKU).
A4: Product name (exact listing title) | B4: SKU (optional) | C4: Materials per unit | D4: Packaging per unit | E4: Labor minutes per unit | F4: Shipping label you pay per unit | G4: Other per-unit fees (FBA, etc.) | H4: Return rate % | I4: Total cost per unit
A5: Lavender Soy Candle 8oz | B5: CAN-LAV | C5: 3.1 | D5: 0.8 | E5: 10 | F5: 4.5 | G5: 0 | H5: 0.02 | I5: =IF(A5="","",C5+D5+E5/60*Settings!$B$12+F5+G5)
A6: Handmade Ceramic Mug - Speckled | B6: MUG-01 | C6: 6 | D6: 1.5 | E6: 45 | F6: 7.8 | G6: 0 | H6: 0.05 | I6: =IF(A6="","",C6+D6+E6/60*Settings!$B$12+F6+G6)
A7: Cute Frog Sticker Pack (5) | B7: STK-5 | C7: 0.9 | D7: 0.2 | E7: 2 | F7: 0.73 | G7: 0 | H7: 0.01 | I7: =IF(A7="","",C7+D7+E7/60*Settings!$B$12+F7+G7)
A8: Linen Tote Bag | B8: TOTE-1 | C8: 5.2 | D8: 0.6 | E8: 15 | F8: 0 | G8: 3.22 | H8: 0.03 | I8: =IF(A8="","",C8+D8+E8/60*Settings!$B$12+F8+G8)
I9: =IF(A9="","",C9+D9+E9/60*Settings!$B$12+F9+G9)
I10: =IF(A10="","",C10+D10+E10/60*Settings!$B$12+F10+G10)
I11: =IF(A11="","",C11+D11+E11/60*Settings!$B$12+F11+G11)
I12: =IF(A12="","",C12+D12+E12/60*Settings!$B$12+F12+G12)
I13: =IF(A13="","",C13+D13+E13/60*Settings!$B$12+F13+G13)
I14: =IF(A14="","",C14+D14+E14/60*Settings!$B$12+F14+G14)
I15: =IF(A15="","",C15+D15+E15/60*Settings!$B$12+F15+G15)
I16: =IF(A16="","",C16+D16+E16/60*Settings!$B$12+F16+G16)
I17: =IF(A17="","",C17+D17+E17/60*Settings!$B$12+F17+G17)
I18: =IF(A18="","",C18+D18+E18/60*Settings!$B$12+F18+G18)
I19: =IF(A19="","",C19+D19+E19/60*Settings!$B$12+F19+G19)
I20: =IF(A20="","",C20+D20+E20/60*Settings!$B$12+F20+G20)
... I204: =IF(A204="","",C204+D204+E204/60*Settings!$B$12+F204+G204)

Sheet Etsy Import
A1: Sale Date | B1: Item Name | C1: Buyer | D1: Quantity | E1: Price | F1: Coupon Code | G1: Coupon Details | H1: Discount Amount | I1: Shipping Discount | J1: Order Shipping | K1: Order Sales Tax | L1: Item Total | M1: Currency | N1: Transaction ID | O1: Listing ID | P1: Order ID | Q1: SKU
A2: 10/01/26 | B2: Lavender Soy Candle 8oz | C2: A | D2: 2 | E2: 18 | H2: 0 | I2: 0 | J2: 0 | K2: 0 | L2: 36 | M2: USD | N2: 1 | O2: 11 | P2: 9001 | Q2: CAN-LAV
A3: 10/02/26 | B3: Handmade Ceramic Mug - Speckled | C3: B | D3: 1 | E3: 28 | H3: 0 | I3: 0 | J3: 0 | K3: 0 | L3: 28 | M3: USD | N3: 2 | O3: 12 | P3: 9002 | Q3: MUG-01
A4: 10/03/26 | B4: Cute Frog Sticker Pack (5) | C4: C | D4: 3 | E4: 6 | H4: 0 | I4: 0 | J4: 1.5 | K4: 0 | L4: 18 | M4: USD | N4: 3 | O4: 13 | P4: 9003 | Q4: STK-5
A5: 10/03/26 | B5: Lavender Soy Candle 8oz | C5: C | D5: 1 | E5: 18 | F5: SAVE10 | H5: 2.4 | I5: 0 | J5: 1.5 | K5: 0 | L5: 18 | M5: USD | N5: 4 | O5: 11 | P5: 9003 | Q5: CAN-LAV
A6: 10/05/26 | B6: Handmade Ceramic Mug - Speckled | C6: D | D6: 2 | E6: 28 | H6: 0 | I6: 0 | J6: 0 | K6: 0 | L6: 56 | M6: USD | N6: 5 | O6: 12 | P6: 9004 | Q6: MUG-01
A7: 10/06/26 | B7: Pressed Flower Bookmark | C7: E | D7: 1 | E7: 9 | H7: 0 | I7: 0 | J7: 0 | K7: 0 | L7: 9 | M7: USD | N7: 6 | O7: 14 | P7: 9005

Sheet Shopify Import
A1: Name | B1: Email | C1: Financial Status | D1: Paid at | E1: Currency | F1: Subtotal | G1: Shipping | H1: Taxes | I1: Total | J1: Discount Code | K1: Discount Amount | L1: Lineitem quantity | M1: Lineitem name | N1: Lineitem price | O1: Lineitem sku
A2: #1001 | B2: x@y.z | C2: paid | D2: 2026-10-02 10:00:00 -0400 | E2: USD | F2: 48 | G2: 5 | H2: 0 | I2: 53 | K2: 0 | L2: 2 | M2: Lavender Soy Candle 8oz | N2: 20 | O2: CAN-LAV
A3: #1001 | L3: 1 | M3: Cute Frog Sticker Pack (5) | N3: 8 | O3: STK-5
A4: #1002 | B4: z@y.x | C4: paid | D4: 2026-10-04 12:00:00 -0400 | E4: USD | F4: 30 | G4: 0 | H4: 0 | I4: 27 | J4: WELCOME | K4: 3 | L4: 1 | M4: Handmade Ceramic Mug - Speckled | N4: 30 | O4: MUG-01

Sheet Manual Sales
A1: Date | B1: Platform | C1: Product name | D1: SKU | E1: Qty | F1: Unit price | G1: Shipping charged | H1: Discount | I1: Order ID | J1: Product (as sold) | K1: SKU | L1: Order ID | M1: Qty | N1: Unit price | O1: Item revenue | P1: Items in order | Q1: Shipping charged | R1: Discount | S1: Gross sales | T1: Product row | U1: Matched product | V1: Platform fees | W1: Product costs | X1: Return allowance | Y1: Net profit
A2: 10/04/26 | B2: Amazon | C2: Linen Tote Bag | D2: TOTE-1 | E2: 3 | F2: 24 | G2: 0 | H2: 0 | I2: AMZ-1 | J2: =IFERROR(IF(C2="","",C2)&"","") | K2: =IFERROR(IF(D2="","",D2)&"","") | L2: =IFERROR(IF(I2="","",I2)&"","") | M2: =IF(J2="","",IFERROR(VALUE(SUBSTITUTE(SUBSTITUTE(IF(E2="","",E2)&"","$",""),",","")),0)) | N2: =IF(J2="","",IFERROR(VALUE(SUBSTITUTE(SUBSTITUTE(IF(F2="","",F2)&"","$",""),",","")),0)) | O2: =IF(J2="","",M2*N2) | P2: =IF(J2="","",IF(L2="",1,COUNTIF($L$2:$L$1501,L2))) | Q2: =IF(J2="","",IFERROR(VALUE(SUBSTITUTE(SUBSTITUTE(IF(G2="","",G2)&"","$",""),",","")),0)/IF("No"="Yes",P2,1)) | R2: =IF(J2="","",IFERROR(VALUE(SUBSTITUTE(SUBSTITUTE(IF(H2="","",H2)&"","$",""),",","")),0)/IF("No"="Yes",P2,1)) | S2: =IF(J2="","",O2+Q2-R2) | T2: =IF(J2="","",IFERROR(IF(K2="",NA(),MATCH(K2,Products!$B$5:$B$204,0)),IFERROR(MATCH(J2,Products!$A$5:$A$204,0),""))) | U2: =IF(J2="","",IF(T2="","⚠ not in Products",INDEX(Products!$A$5:$A$204,T2))) | V2: =IF(J2="","",S2*(IFERROR(INDEX(Settings!$B$5:$B$9,MATCH($B2,Settings!$A$5:$A$9,0)),0)+IFERROR(INDEX(Settings!$E$5:$E$9,MATCH($B2,Settings!$A$5:$A$9,0)),0)+IFERROR(INDEX(Settings!$G$5:$G$9,MATCH($B2,Settings!$A$5:$A$9,0)),0))+(IFERROR(INDEX(Settings!$C$5:$C$9,MATCH($B2,Settings!$A$5:$A$9,0)),0)+IFERROR(INDEX(Settings!$F$5:$F$9,MATCH($B2,Settings!$A$5:$A$9,0)),0))/P2+IFERROR(INDEX(Settings!$D$5:$D$9,MATCH($B2,Settings!$A$5:$A$9,0)),0)*M2) | W2: =IF(J2="","",IF(T2="",0,M2*INDEX(Products!$I$5:$I$204,T2))) | X2: =IF(J2="","",IF(T2="",0,S2*INDEX(Products!$H$5:$H$204,T2))) | Y2: =IF(J2="","",S2-V2-W2-X2)
A3: 10/05/26 | B3: Other | C3: Lavender Soy Candle 8oz | E3: 4 | F3: 15 | G3: 0 | H3: 0 | I3: MKT-1 | J3: =IFERROR(IF(C3="","",C3)&"","") | K3: =IFERROR(IF(D3="","",D3)&"","") | L3: =IFERROR(IF(I3="","",I3)&"","") | M3: =IF(J3="","",IFERROR(VALUE(SUBSTITUTE(SUBSTITUTE(IF(E3="","",E3)&"","$",""),",","")),0)) | N3: =IF(J3="","",IFERROR(VALUE(SUBSTITUTE(SUBSTITUTE(IF(F3="","",F3)&"","$",""),",","")),0)) | O3: =IF(J3="","",M3*N3) | P3: =IF(J3="","",IF(L3="",1,COUNTIF($L$2:$L$1501,L3))) | Q3: =IF(J3="","",IFERROR(VALUE(SUBSTITUTE(SUBSTITUTE(IF(G3="","",G3)&"","$",""),",","")),0)/IF("No"="Yes",P3,1)) | R3: =IF(J3="","",IFERROR(VALUE(SUBSTITUTE(SUBSTITUTE(IF(H3="","",H3)&"","$",""),",","")),0)/IF("No"="Yes",P3,1)) | S3: =IF(J3="","",O3+Q3-R3) | T3: =IF(J3="","",IFERROR(IF(K3="",NA(),MATCH(K3,Products!$B$5:$B$204,0)),IFERROR(MATCH(J3,Products!$A$5:$A$204,0),""))) | U3: =IF(J3="","",IF(T3="","⚠ not in Products",INDEX(Products!$A$5:$A$204,T3))) | V3: =IF(J3="","",S3*(IFERROR(INDEX(Settings!$B$5:$B$9,MATCH($B3,Settings!$A$5:$A$9,0)),0)+IFERROR(INDEX(Settings!$E$5:$E$9,MATCH($B3,Settings!$A$5:$A$9,0)),0)+IFERROR(INDEX(Settings!$G$5:$G$9,MATCH($B3,Settings!$A$5:$A$9,0)),0))+(IFERROR(INDEX(Settings!$C$5:$C$9,MATCH($B3,Settings!$A$5:$A$9,0)),0)+IFERROR(INDEX(Settings!$F$5:$F$9,MATCH($B3,Settings!$A$5:$A$9,0)),0))/P3+IFERROR(INDEX(Settings!$D$5:$D$9,MATCH($B3,Settings!$A$5:$A$9,0)),0)*M3) | W3: =IF(J3="","",IF(T3="",0,M3*INDEX(Products!$I$5:$I$204,T3))) | X3: =IF(J3="","",IF(T3="",0,S3*INDEX(Products!$H$5:$H$204,T3))) | Y3: =IF(J3="","",S3-V3-W3-X3)
J4: =IFERROR(IF(C4="","",C4)&"","") | K4: =IFERROR(IF(D4="","",D4)&"","") | L4: =IFERROR(IF(I4="","",I4)&"","") | M4: =IF(J4="","",IFERROR(VALUE(SUBSTITUTE(SUBSTITUTE(IF(E4="","",E4)&"","$",""),",","")),0)) | N4: =IF(J4="","",IFERROR(VALUE(SUBSTITUTE(SUBSTITUTE(IF(F4="","",F4)&"","$",""),",","")),0)) | O4: =IF(J4="","",M4*N4) | P4: =IF(J4="","",IF(L4="",1,COUNTIF($L$2:$L$1501,L4))) | Q4: =IF(J4="","",IFERROR(VALUE(SUBSTITUTE(SUBSTITUTE(IF(G4="","",G4)&"","$",""),",","")),0)/IF("No"="Yes",P4,1)) | R4: =IF(J4="","",IFERROR(VALUE(SUBSTITUTE(SUBSTITUTE(IF(H4="","",H4)&"","$",""),",","")),0)/IF("No"="Yes",P4,1)) | S4: =IF(J4="","",O4+Q4-R4) | T4: =IF(J4="","",IFERROR(IF(K4="",NA(),MATCH(K4,Products!$B$5:$B$204,0)),IFERROR(MATCH(J4,Products!$A$5:$A$204,0),""))) | U4: =IF(J4="","",IF(T4="","⚠ not in Products",INDEX(Products!$A$5:$A$204,T4))) | V4: =IF(J4="","",S4*(IFERROR(INDEX(Settings!$B$5:$B$9,MATCH($B4,Settings!$A$5:$A$9,0)),0)+IFERROR(INDEX(Settings!$E$5:$E$9,MATCH($B4,Settings!$A$5:$A$9,0)),0)+IFERROR(INDEX(Settings!$G$5:$G$9,MATCH($B4,Settings!$A$5:$A$9,0)),0))+(IFERROR(INDEX(Settings!$C$5:$C$9,MATCH($B4,Settings!$A$5:$A$9,0)),0)+IFERROR(INDEX(Settings!$F$5:$F$9,MATCH($B4,Settings!$A$5:$A$9,0)),0))/P4+IFERROR(INDEX(Settings!$D$5:$D$9,MATCH($B4,Settings!$A$5:$A$9,0)),0)*M4) | W4: =IF(J4="","",IF(T4="",0,M4*INDEX(Products!$I$5:$I$204,T4))) | X4: =IF(J4="","",IF(T4="",0,S4*INDEX(Products!$H$5:$H$204,T4))) | Y4: =IF(J4="","",S4-V4-W4-X4)
J5: =IFERROR(IF(C5="","",C5)&"","") | K5: =IFERROR(IF(D5="","",D5)&"","") | L5: =IFERROR(IF(I5="","",I5)&"","") | M5: =IF(J5="","",IFERROR(VALUE(SUBSTITUTE(SUBSTITUTE(IF(E5="","",E5)&"","$",""),",","")),0)) | N5: =IF(J5="","",IFERROR(VALUE(SUBSTITUTE(SUBSTITUTE(IF(F5="","",F5)&"","$",""),",","")),0)) | O5: =IF(J5="","",M5*N5) | P5: =IF(J5="","",IF(L5="",1,COUNTIF($L$2:$L$1501,L5))) | Q5: =IF(J5="","",IFERROR(VALUE(SUBSTITUTE(SUBSTITUTE(IF(G5="","",G5)&"","$",""),",","")),0)/IF("No"="Yes",P5,1)) | R5: =IF(J5="","",IFERROR(VALUE(SUBSTITUTE(SUBSTITUTE(IF(H5="","",H5)&"","$",""),",","")),0)/IF("No"="Yes",P5,1)) | S5: =IF(J5="","",O5+Q5-R5) | T5: =IF(J5="","",IFERROR(IF(K5="",NA(),MATCH(K5,Products!$B$5:$B$204,0)),IFERROR(MATCH(J5,Products!$A$5:$A$204,0),""))) | U5: =IF(J5="","",IF(T5="","⚠ not in Products",INDEX(Products!$A$5:$A$204,T5))) | V5: =IF(J5="","",S5*(IFERROR(INDEX(Settings!$B$5:$B$9,MATCH($B5,Settings!$A$5:$A$9,0)),0)+IFERROR(INDEX(Settings!$E$5:$E$9,MATCH($B5,Settings!$A$5:$A$9,0)),0)+IFERROR(INDEX(Settings!$G$5:$G$9,MATCH($B5,Settings!$A$5:$A$9,0)),0))+(IFERROR(INDEX(Settings!$C$5:$C$9,MATCH($B5,Settings!$A$5:$A$9,0)),0)+IFERROR(INDEX(Settings!$F$5:$F$9,MATCH($B5,Settings!$A$5:$A$9,0)),0))/P5+IFERROR(INDEX(Settings!$D$5:$D$9,MATCH($B5,Settings!$A$5:$A$9,0)),0)*M5) | W5: =IF(J5="","",IF(T5="",0,M5*INDEX(Products!$I$5:$I$204,T5))) | X5: =IF(J5="","",IF(T5="",0,S5*INDEX(Products!$H$5:$H$204,T5))) | Y5: =IF(J5="","",S5-V5-W5-X5)
